<mujoco model="A1_URDF_0607_0028">
  <compiler angle="radian" meshdir="../meshes/"/>

  <asset>
    <mesh name="base_link" file="base_link.STL"/>
    <mesh name="arm_seg1" file="arm_seg1.STL"/>
    <mesh name="arm_seg2" file="arm_seg2.STL"/>
    <mesh name="arm_seg3" file="arm_seg3.STL"/>
    <mesh name="arm_seg4" file="arm_seg4.STL"/>
    <mesh name="arm_seg5" file="arm_seg5.STL"/>
    <mesh name="arm_seg6" file="arm_seg6.STL"/>
    <mesh name="gripper1" file="gripper1.STL"/>
    <mesh name="gripper2" file="gripper2.STL"/>
  </asset>

  <worldbody>
    <geom type="mesh" contype="0" conaffinity="0" group="1" density="0" rgba="0.79216 0.81961 0.93333 1" mesh="base_link"/>
    <geom type="mesh" rgba="0.79216 0.81961 0.93333 1" mesh="base_link"/>
    <body name="arm_seg1" pos="-0.0011147 0 0.0892" quat="-3.67321e-06 0 0 1">
      <inertial pos="-1.4403e-06 -0.00074041 0.056573" quat="0.707084 0.00122867 -0.00107609 0.707127" mass="1.391" diaginertia="0.000708573 0.00058101 0.000445827"/>
      <joint name="arm_joint1" pos="0 0 0" axis="0 0 1" range="-2.8798 2.8798" actuatorfrcrange="-40 40"/>
      <geom type="mesh" contype="0" conaffinity="0" group="1" density="0" rgba="0.79216 0.81961 0.93333 1" mesh="arm_seg1"/>
      <geom type="mesh" rgba="0.79216 0.81961 0.93333 1" mesh="arm_seg1"/>
      <body name="arm_seg2" pos="0 -4e-05 0.0615" quat="0.707105 0.707108 0 0">
        <inertial pos="0.23622 0.016356 9.154e-05" quat="0.484393 0.48518 0.524693 0.504639" mass="1.3" diaginertia="0.00761886 0.00757469 0.000578276"/>
        <joint name="arm_joint2" pos="0 0 0" axis="0 0 1" range="0 3.1415" actuatorfrcrange="-40 40"/>
        <geom type="mesh" contype="0" conaffinity="0" group="1" density="0" rgba="0.79216 0.81961 0.93333 1" mesh="arm_seg2"/>
        <geom type="mesh" rgba="0.79216 0.81961 0.93333 1" mesh="arm_seg2"/>
        <body name="arm_seg3" pos="0.34928 0.02 0" quat="0.707105 0 0 0.707108">
          <inertial pos="0.054443 0.045347 0.00042807" quat="0.595278 0.471808 -0.522016 0.387995" mass="0.818" diaginertia="0.00149749 0.00144877 0.00053598"/>
          <joint name="arm_joint3" pos="0 0 0" axis="0 0 1" range="-3.3161 0" actuatorfrcrange="-27 27"/>
          <geom type="mesh" contype="0" conaffinity="0" group="1" density="0" rgba="0.79216 0.81961 0.93333 1" mesh="arm_seg3"/>
          <geom type="mesh" rgba="0.79216 0.81961 0.93333 1" mesh="arm_seg3"/>
          <body name="arm_seg4" pos="0.07 -0.00395 -4e-05" quat="0.499998 -0.5 0.5 0.500002">
            <inertial pos="7.6256e-07 -0.0021448 0.27415" quat="0.70651 0.0169198 -0.0168252 0.707301" mass="0.816" diaginertia="0.000101779 9.7042e-05 8.44616e-05"/>
            <joint name="arm_joint4" pos="0 0 0" axis="0 0 1" range="-2.8798 2.8798" actuatorfrcrange="-7 7"/>
            <geom type="mesh" contype="0" conaffinity="0" group="1" density="0" rgba="1 1 1 1" mesh="arm_seg4"/>
            <geom type="mesh" rgba="1 1 1 1" mesh="arm_seg4"/>
            <body name="arm_seg5" pos="0 0 0.2776" quat="-2.59734e-06 2.59735e-06 -0.707108 0.707105">
              <inertial pos="-3.9997e-06 -0.05431 0.0034482" quat="0.477398 0.87868 0.00338218 -0.000840949" mass="0.801" diaginertia="0.00011332 0.000109027 7.34689e-05"/>
              <joint name="arm_joint5" pos="0 0 0" axis="0 0 1" range="-1.6581 1.6581" actuatorfrcrange="-7 7"/>
              <geom type="mesh" contype="0" conaffinity="0" group="1" density="0" rgba="1 1 1 1" mesh="arm_seg5"/>
              <geom type="mesh" rgba="1 1 1 1" mesh="arm_seg5"/>
              <body name="arm_seg6" pos="0 -0.1575 -0.00023266" quat="0.707105 0.707108 0 0">
                <inertial pos="1.93719e-06 -8.51884e-08 -0.0260973" quat="0.998261 9.34938e-07 -3.37378e-05 -0.0589521" mass="0.579" diaginertia="0.00050649 0.000503906 7.9941e-05"/>
                <joint name="arm_joint6" pos="0 0 0" axis="0 0 1" range="-2.8798 2.8798" actuatorfrcrange="-7 7"/>
                <geom type="mesh" contype="0" conaffinity="0" group="1" density="0" rgba="0.79216 0.81961 0.93333 1" mesh="arm_seg6"/>
                <geom type="mesh" rgba="0.79216 0.81961 0.93333 1" mesh="arm_seg6"/>
                <geom pos="0.014 -0.011914 0.003125" quat="-0.499979 0.500023 0.499977 0.500021" type="mesh" contype="0" conaffinity="0" group="1" density="0" rgba="0.79216 0.81961 0.93333 1" mesh="gripper1"/>
                <geom pos="0.014 -0.011914 0.003125" quat="-0.499979 0.500023 0.499977 0.500021" type="mesh" rgba="0.79216 0.81961 0.93333 1" mesh="gripper1"/>
                <geom pos="-0.014 0.011914 0.003125" quat="0.500025 0.499977 -0.500023 0.499975" type="mesh" contype="0" conaffinity="0" group="1" density="0" rgba="0.79216 0.81961 0.93333 1" mesh="gripper2"/>
                <geom pos="-0.014 0.011914 0.003125" quat="0.500025 0.499977 -0.500023 0.499975" type="mesh" rgba="0.79216 0.81961 0.93333 1" mesh="gripper2"/>
              </body>
            </body>
          </body>
        </body>
      </body>
    </body>
  </worldbody>
</mujoco>
