<mujoco model="aliengo">
  <compiler angle="radian" meshdir="../meshes/" />

  <!-- <option integrator="RK4" solver="PGS" /> -->

  <option timestep='0.005' iterations='50' solver='PGS' gravity='0 0 -9.81'/>
  <visual>
    <global fovy="60" />
  </visual>

  <default>
      <joint damping="0.05" armature="0.01" frictionloss="0.2"/>
      <!-- <joint damping="0.05" armature="0.00" frictionloss="0.2"/> -->
    <default class="visual">
      <geom contype="2" conaffinity="2" mass="0" group='2'/>
    </default>

  </default>

  <asset>
    <mesh name="trunk" file="trunk.stl" />
    <mesh name="hip" file="hip.stl" />
    <mesh name="thigh_mirror" file="thigh_mirror.stl" />
    <mesh name="calf" file="calf.stl" />
    <mesh name="thigh" file="thigh.stl" />
    <texture name="texplane" type="2d" builtin="checker" rgb1=".2 .3 .4" rgb2=".1 0.15 0.2"
        width="512" height="512" mark="cross" markrgb=".8 .8 .8"/>
    <material name="matplane" reflectance="0." texture="texplane" texrepeat="1 1" texuniform="true"/>
    <mesh name="base_link" file="base_link.STL"/>
    <mesh name="arm_seg1" file="arm_seg1.STL"/>
    <mesh name="arm_seg2" file="arm_seg2.STL"/>
    <mesh name="arm_seg3" file="arm_seg3.STL"/>
    <mesh name="arm_seg4" file="arm_seg4.STL"/>
    <mesh name="arm_seg5" file="arm_seg5.STL"/>
    <mesh name="arm_seg6" file="arm_seg6.STL"/>
    <mesh name="gripper1" file="gripper1.STL"/>
    <mesh name="gripper2" file="gripper2.STL"/>
  </asset>

  <worldbody>
    <light directional="true" diffuse=".4 .4 .4" specular="0.1 0.1 0.1" pos="0 0 5.0" dir="0 0 -1"
      castshadow="false" />
    <light directional="true" diffuse=".6 .6 .6" specular="0.2 0.2 0.2" pos="0 0 4" dir="0 0 -1" />
    <geom name="ground" type="plane" size="0 0 1" pos="0.001 0 0" quat="1 0 0 0" material="matplane"
      condim="1" conaffinity='15' />

    <body name="arm_base_shadow" pos="0.08 0 0.07">
    <freejoint/>
    <inertial pos='0 0 0' mass="1.391" diaginertia="0.000708573 0.00058101 0.000445827"/>
    <geom type="mesh" rgba="0.79216 0.81961 0.93333 1" mesh="base_link" class='visual'/>
    <geom type="mesh" rgba="0.79216 0.81961 0.93333 1" mesh="base_link" class='visual'/>
    <body name="arm_seg1_shadow" pos="-0.0011147 0 0.0892" quat="-3.67321e-06 0 0 1">
      <inertial pos="-1.4403e-06 -0.00074041 0.056573" quat="0.707084 0.00122867 -0.00107609 0.707127" mass="1.391" diaginertia="0.000708573 0.00058101 0.000445827"/>
      <joint name="arm_joint1_shadow" pos="0 0 0" axis="0 0 1" range="-2.8798 2.8798" actuatorfrcrange="-40 40"/>
      <geom type="mesh" rgba="0.79216 0.81961 0.93333 1" mesh="arm_seg1" class='visual'/>
      <geom type="mesh" rgba="0.79216 0.81961 0.93333 1" mesh="arm_seg1" class='visual'/>
      <body name="arm_seg2_shadow" pos="0 -4e-05 0.0615" quat="0.707105 0.707108 0 0">
        <inertial pos="0.23622 0.016356 9.154e-05" quat="0.484393 0.48518 0.524693 0.504639" mass="1.3" diaginertia="0.00761886 0.00757469 0.000578276"/>
        <joint name="arm_joint2_shadow" pos="0 0 0" axis="0 0 1" range="0 3.1415" actuatorfrcrange="-40 40"/>
        <geom type="mesh" rgba="0.79216 0.81961 0.93333 1" mesh="arm_seg2" class='visual'/>
        <geom type="mesh" rgba="0.79216 0.81961 0.93333 1" mesh="arm_seg2" class='visual'/>
        <body name="arm_seg3_shadow" pos="0.34928 0.02 0" quat="0.707105 0 0 0.707108">
          <inertial pos="0.054443 0.045347 0.00042807" quat="0.595278 0.471808 -0.522016 0.387995" mass="0.818" diaginertia="0.00149749 0.00144877 0.00053598"/>
          <joint name="arm_joint3_shadow" pos="0 0 0" axis="0 0 1" range="-3.3161 0" actuatorfrcrange="-27 27"/>
          <geom type="mesh" rgba="0.79216 0.81961 0.93333 1" mesh="arm_seg3" class='visual'/>
          <geom type="mesh" rgba="0.79216 0.81961 0.93333 1" mesh="arm_seg3" class='visual'/>
          <body name="arm_seg4_shadow" pos="0.07 -0.00395 -4e-05" quat="0.499998 -0.5 0.5 0.500002">
            <inertial pos="7.6256e-07 -0.0021448 0.27415" quat="0.70651 0.0169198 -0.0168252 0.707301" mass="0.816" diaginertia="0.000101779 9.7042e-05 8.44616e-05"/>
            <joint name="arm_joint4_shadow" pos="0 0 0" axis="0 0 1" range="-2.8798 2.8798" actuatorfrcrange="-7 7"/>
            <geom type="mesh" rgba="1 1 1 1" mesh="arm_seg4" class='visual'/>
            <geom type="mesh" rgba="1 1 1 1" mesh="arm_seg4" class='visual'/>
            <body name="arm_seg5_shadow" pos="0 0 0.2776" quat="-2.59734e-06 2.59735e-06 -0.707108 0.707105">
              <inertial pos="-3.9997e-06 -0.05431 0.0034482" quat="0.477398 0.87868 0.00338218 -0.000840949" mass="0.801" diaginertia="0.00011332 0.000109027 7.34689e-05"/>
              <joint name="arm_joint5_shadow" pos="0 0 0" axis="0 0 1" range="-1.6581 1.6581" actuatorfrcrange="-7 7"/>
              <geom type="mesh" rgba="1 1 1 1" mesh="arm_seg5" class='visual'/>
              <geom type="mesh" rgba="1 1 1 1" mesh="arm_seg5" class='visual'/>
              <body name="arm_seg6_shadow" pos="0 -0.1575 -0.00023266" quat="0.707105 0.707108 0 0">
                <inertial pos="1.93719e-06 -8.51884e-08 -0.0260973" quat="0.998261 9.34938e-07 -3.37378e-05 -0.0589521" mass="0.579" diaginertia="0.00050649 0.000503906 7.9941e-05"/>
                <!-- <joint name="arm_joint6" pos="0 0 0" axis="0 0 1" range="-2.8798 2.8798" actuatorfrcrange="-7 7"/> -->
                <geom type="mesh" rgba="0.79216 0.81961 0.93333 1" mesh="arm_seg6" class='visual'/>
                <geom type="mesh" rgba="0.79216 0.81961 0.93333 1" mesh="arm_seg6" class='visual'/>
                <geom pos="0.014 -0.011914 0.003125" quat="-0.499979 0.500023 0.499977 0.500021" type="mesh" rgba="0.79216 0.81961 0.93333 1" mesh="gripper1" class='visual'/>
                <geom pos="0.014 -0.011914 0.003125" quat="-0.499979 0.500023 0.499977 0.500021" type="mesh" rgba="0.79216 0.81961 0.93333 1" mesh="gripper1" class='visual'/>
                <geom pos="-0.014 0.011914 0.003125" quat="0.500025 0.499977 -0.500023 0.499975" type="mesh" rgba="0.79216 0.81961 0.93333 1" mesh="gripper2" class='visual'/>
                <geom pos="-0.014 0.011914 0.003125" quat="0.500025 0.499977 -0.500023 0.499975" type="mesh" rgba="0.79216 0.81961 0.93333 1" mesh="gripper2" class='visual'/>
              </body>
            </body>
          </body>
        </body>
      </body>
    </body>
    </body>


    <body name="base" pos="0.0 0.0 0.35">

    <body name="arm_base" pos="0.08 0 0.07">
    <geom type="mesh" contype="0" conaffinity="0" group="1" density="0" rgba="0.79216 0.81961 0.93333 1" mesh="base_link"/>
    <geom type="mesh" rgba="0.79216 0.81961 0.93333 1" mesh="base_link"/>
    <body name="arm_seg1" pos="-0.0011147 0 0.0892" quat="-3.67321e-06 0 0 1">
      <inertial pos="-1.4403e-06 -0.00074041 0.056573" quat="0.707084 0.00122867 -0.00107609 0.707127" mass="1.391" diaginertia="0.000708573 0.00058101 0.000445827"/>
      <joint name="arm_joint1" pos="0 0 0" axis="0 0 1" range="-2.8798 2.8798" actuatorfrcrange="-40 40"/>
      <geom type="mesh" contype="0" conaffinity="0" group="1" density="0" rgba="0.79216 0.81961 0.93333 1" mesh="arm_seg1"/>
      <geom type="mesh" rgba="0.79216 0.81961 0.93333 1" mesh="arm_seg1"/>
      <body name="arm_seg2" pos="0 -4e-05 0.0615" quat="0.707105 0.707108 0 0">
        <inertial pos="0.23622 0.016356 9.154e-05" quat="0.484393 0.48518 0.524693 0.504639" mass="1.3" diaginertia="0.00761886 0.00757469 0.000578276"/>
        <joint name="arm_joint2" pos="0 0 0" axis="0 0 1" range="0 3.1415" actuatorfrcrange="-40 40"/>
        <geom type="mesh" contype="0" conaffinity="0" group="1" density="0" rgba="0.79216 0.81961 0.93333 1" mesh="arm_seg2"/>
        <geom type="mesh" rgba="0.79216 0.81961 0.93333 1" mesh="arm_seg2"/>
        <body name="arm_seg3" pos="0.34928 0.02 0" quat="0.707105 0 0 0.707108">
          <inertial pos="0.054443 0.045347 0.00042807" quat="0.595278 0.471808 -0.522016 0.387995" mass="0.818" diaginertia="0.00149749 0.00144877 0.00053598"/>
          <joint name="arm_joint3" pos="0 0 0" axis="0 0 1" range="-3.3161 0" actuatorfrcrange="-27 27"/>
          <geom type="mesh" contype="0" conaffinity="0" group="1" density="0" rgba="0.79216 0.81961 0.93333 1" mesh="arm_seg3"/>
          <geom type="mesh" rgba="0.79216 0.81961 0.93333 1" mesh="arm_seg3"/>
          <body name="arm_seg4" pos="0.07 -0.00395 -4e-05" quat="0.499998 -0.5 0.5 0.500002">
            <inertial pos="7.6256e-07 -0.0021448 0.27415" quat="0.70651 0.0169198 -0.0168252 0.707301" mass="0.816" diaginertia="0.000101779 9.7042e-05 8.44616e-05"/>
            <joint name="arm_joint4" pos="0 0 0" axis="0 0 1" range="-2.8798 2.8798" actuatorfrcrange="-7 7"/>
            <geom type="mesh" contype="0" conaffinity="0" group="1" density="0" rgba="1 1 1 1" mesh="arm_seg4"/>
            <geom type="mesh" rgba="1 1 1 1" mesh="arm_seg4"/>
            <body name="arm_seg5" pos="0 0 0.2776" quat="-2.59734e-06 2.59735e-06 -0.707108 0.707105">
              <inertial pos="-3.9997e-06 -0.05431 0.0034482" quat="0.477398 0.87868 0.00338218 -0.000840949" mass="0.801" diaginertia="0.00011332 0.000109027 7.34689e-05"/>
              <joint name="arm_joint5" pos="0 0 0" axis="0 0 1" range="-1.6581 1.6581" actuatorfrcrange="-7 7"/>
              <geom type="mesh" contype="0" conaffinity="0" group="1" density="0" rgba="1 1 1 1" mesh="arm_seg5"/>
              <geom type="mesh" rgba="1 1 1 1" mesh="arm_seg5"/>
              <body name="arm_seg6" pos="0 -0.1575 -0.00023266" quat="0.707105 0.707108 0 0">
                <inertial pos="1.93719e-06 -8.51884e-08 -0.0260973" quat="0.998261 9.34938e-07 -3.37378e-05 -0.0589521" mass="0.579" diaginertia="0.00050649 0.000503906 7.9941e-05"/>
                <!-- <joint name="arm_joint6" pos="0 0 0" axis="0 0 1" range="-2.8798 2.8798" actuatorfrcrange="-7 7"/> -->
                <geom type="mesh" contype="0" conaffinity="0" group="1" density="0" rgba="0.79216 0.81961 0.93333 1" mesh="arm_seg6"/>
                <geom type="mesh" rgba="0.79216 0.81961 0.93333 1" mesh="arm_seg6"/>
                <geom pos="0.014 -0.011914 0.003125" quat="-0.499979 0.500023 0.499977 0.500021" type="mesh" contype="0" conaffinity="0" group="1" density="0" rgba="0.79216 0.81961 0.93333 1" mesh="gripper1"/>
                <geom pos="0.014 -0.011914 0.003125" quat="-0.499979 0.500023 0.499977 0.500021" type="mesh" rgba="0.79216 0.81961 0.93333 1" mesh="gripper1"/>
                <geom pos="-0.014 0.011914 0.003125" quat="0.500025 0.499977 -0.500023 0.499975" type="mesh" contype="0" conaffinity="0" group="1" density="0" rgba="0.79216 0.81961 0.93333 1" mesh="gripper2"/>
                <geom pos="-0.014 0.011914 0.003125" quat="0.500025 0.499977 -0.500023 0.499975" type="mesh" rgba="0.79216 0.81961 0.93333 1" mesh="gripper2"/>
              </body>
            </body>
          </body>
        </body>
      </body>
    </body>
    </body>

      <geom type="mesh" contype="0" conaffinity="0" group="1" density="0"
        rgba="1 0.423529 0.0392157 1" mesh="trunk" />

      <inertial pos="0.008811 0.003839 0.000273" mass="11.644" diaginertia="0.051944892 0.24693924 0.270948307" />
      <joint type='slide' axis='1 0 0' limited='false' />
      <joint type='slide' axis='0 1 0' limited='false' />
      <joint type='slide' axis='0 0 1' limited='false' />
      <joint type='ball' limited='false' />
      <site name='imu' size='0.01' pos='0.0 0 0.0'/>

      <geom size="0.0005 0.0005 0.0005" type="box" contype="0" conaffinity="0" group="1" density="0" />
      <geom size="0.3235 0.075 0.056" type="box" rgba="1 0.423529 0.0392157 1" />
      <geom size="0.0005 0.0005 0.0005" type="box" contype="0" conaffinity="0" group="1" density="0"
        rgba="0.8 0 0 1" />
      <geom size="0.0005 0.0005 0.0005" type="box" rgba="0.8 0 0 1" />
      <geom size="0.035 0.01" pos="0.139985 -0.051 0" quat="0.707107 0 0.707107 0" type="cylinder"
        contype="0" conaffinity="0" group="1" density="0" rgba="0 0.8 0 1" />
      <geom size="0.035 0.01" pos="0.139985 -0.051 0" quat="0.707107 0 0.707107 0" type="cylinder"
        rgba="0 0.8 0 1" />
      <geom size="0.035 0.01" pos="0.139985 0.051 0" quat="0.707107 0 0.707107 0" type="cylinder"
        contype="0" conaffinity="0" group="1" density="0" rgba="0 0.8 0 1" />
      <geom size="0.035 0.01" pos="0.139985 0.051 0" quat="0.707107 0 0.707107 0" type="cylinder"
        rgba="0 0.8 0 1" />
      <geom size="0.035 0.01" pos="-0.139985 -0.051 0" quat="0.707107 0 0.707107 0" type="cylinder"
        contype="0" conaffinity="0" group="1" density="0" rgba="0 0.8 0 1" />
      <geom size="0.035 0.01" pos="-0.139985 -0.051 0" quat="0.707107 0 0.707107 0" type="cylinder"
        rgba="0 0.8 0 1" />
      <geom size="0.035 0.01" pos="-0.139985 0.051 0" quat="0.707107 0 0.707107 0" type="cylinder"
        contype="0" conaffinity="0" group="1" density="0" rgba="0 0.8 0 1" />
      <geom size="0.035 0.01" pos="-0.139985 0.051 0" quat="0.707107 0 0.707107 0" type="cylinder"
        rgba="0 0.8 0 1" />
      <body name="FR_hip" pos="0.2407 -0.051 0">
        <inertial pos="-0.0206763 -0.0161444 -1.39762e-05" quat="0.58092 0.574831 0.412459 0.402465"
          mass="2.139" diaginertia="0.0043606 0.0043277 0.00233028" />
        <joint name="FR_hip_joint" pos="0 0 0" axis="1 0 0" range="-1.22173 1.22173"
          actuatorfrcrange="-35.278 35.278" />
        <geom quat="0 1 0 0" type="mesh" contype="0" conaffinity="0" group="1" density="0"
          rgba="1 0.423529 0.0392157 1" mesh="hip" />
        <geom size="0.046 0.0209" pos="0 -0.083 0" quat="0.707107 0.707107 0 0" type="cylinder"
          rgba="1 0.423529 0.0392157 1" />
        <geom size="0.035 0.01" pos="0 -0.0298 0" quat="0.707107 0.707107 0 0" type="cylinder"
          contype="0" conaffinity="0" group="1" density="0" rgba="0 0.8 0 1" />
        <geom size="0.035 0.01" pos="0 -0.0298 0" quat="0.707107 0.707107 0 0" type="cylinder"
          rgba="0 0.8 0 1" />
        <body name="FR_thigh" pos="0 -0.0868 0">
          <inertial pos="-0.00464705 0.0202825 -0.039947"
            quat="0.994998 -0.0906147 0.0414285 -0.0071304" mass="0.771"
            diaginertia="0.00560787 0.004847 0.00135111" />
          <joint name="FR_thigh_joint" pos="0 0 0" axis="0 1 0" actuatorfrcrange="-35.278 35.278" />
          <geom type="mesh" contype="0" conaffinity="0" group="1" density="0"
            rgba="1 0.423529 0.0392157 1" mesh="thigh_mirror" />
          <geom size="0.125 0.0187 0.0215" pos="0 0 -0.125" quat="0.707107 0 0.707107 0" type="box"
            rgba="1 0.423529 0.0392157 1" />
          <!-- <geom size="0.035 0.01" pos="0 0.0997 0" quat="0.707107 0.707107 0 0" type="cylinder"
            contype="0" conaffinity="0" group="1" density="0" rgba="0 0.8 0 1" />
          <geom size="0.035 0.01" pos="0 0.0997 0" quat="0.707107 0.707107 0 0" type="cylinder"
            rgba="0 0.8 0 1" /> -->
          <body name="FR_calf" pos="0 0 -0.25">
            <inertial pos="0.00215606 4.88427e-05 -0.166671"
              quat="0.708049 0.000982931 0.00120829 0.706161" mass="0.267"
              diaginertia="0.00269606 0.00268354 5.47714e-05" />
            <joint name="FR_calf_joint" pos="0 0 0" axis="0 1 0" range="-2.77507 -0.645772"
              actuatorfrcrange="-44.4 44.4" />
            <geom type="mesh" contype="0" conaffinity="0" group="1" density="0"
              rgba="1 0.423529 0.0392157 1" mesh="calf" />
            <geom size="0.125 0.0104 0.008" pos="0 0 -0.125" quat="0.707107 0 0.707107 0" type="box"
              rgba="1 0.423529 0.0392157 1" />
            <geom size="0.0165" pos="0 0 -0.25" contype="0" conaffinity="0" group="1" density="0"
              rgba="0 0.8 0 1" />
            <geom size="0.0265" pos="0 0 -0.25" rgba="0 0.8 0 1" />
          </body>
        </body>
      </body>
      <body name="FL_hip" pos="0.2407 0.051 0">
        <inertial pos="-0.0206763 0.0161444 -1.39762e-05" quat="0.402465 0.412459 0.574831 0.58092"
          mass="2.139" diaginertia="0.0043606 0.0043277 0.00233028" />
        <joint name="FL_hip_joint" pos="0 0 0" axis="1 0 0" range="-1.22173 1.22173"
          actuatorfrcrange="-35.278 35.278" />
        <geom type="mesh" contype="0" conaffinity="0" group="1" density="0"
          rgba="1 0.423529 0.0392157 1" mesh="hip" />
        <geom size="0.046 0.0209" pos="0 0.083 0" quat="0.707107 0.707107 0 0" type="cylinder"
          rgba="1 0.423529 0.0392157 1" />
        <geom size="0.035 0.01" pos="0 0.0298 0" quat="0.707107 0.707107 0 0" type="cylinder"
          contype="0" conaffinity="0" group="1" density="0" rgba="0 0.8 0 1" />
        <geom size="0.035 0.01" pos="0 0.0298 0" quat="0.707107 0.707107 0 0" type="cylinder"
          rgba="0 0.8 0 1" />
        <body name="FL_thigh" pos="0 0.0868 0">
          <inertial pos="-0.00464705 -0.0202825 -0.039947"
            quat="0.994998 0.0906147 0.0414285 0.0071304" mass="0.771"
            diaginertia="0.00560787 0.004847 0.00135111" />
          <joint name="FL_thigh_joint" pos="0 0 0" axis="0 1 0" actuatorfrcrange="-35.278 35.278" />
          <geom type="mesh" contype="0" conaffinity="0" group="1" density="0"
            rgba="1 0.423529 0.0392157 1" mesh="thigh" />
          <geom size="0.125 0.0187 0.0215" pos="0 0 -0.125" quat="0.707107 0 0.707107 0" type="box"
            rgba="1 0.423529 0.0392157 1" />
          <!-- <geom size="0.035 0.01" pos="0 -0.0997 0" quat="0.707107 0.707107 0 0" type="cylinder"
            contype="0" conaffinity="0" group="1" density="0" rgba="0 0.8 0 1" />
          <geom size="0.035 0.01" pos="0 -0.0997 0" quat="0.707107 0.707107 0 0" type="cylinder"
            rgba="0 0.8 0 1" /> -->
          <body name="FL_calf" pos="0 0 -0.25">
            <inertial pos="0.00215606 4.88427e-05 -0.166671"
              quat="0.708049 0.000982931 0.00120829 0.706161" mass="0.267"
              diaginertia="0.00269606 0.00268354 5.47714e-05" />
            <joint name="FL_calf_joint" pos="0 0 0" axis="0 1 0" range="-2.77507 -0.645772"
              actuatorfrcrange="-44.4 44.4" />
            <geom type="mesh" contype="0" conaffinity="0" group="1" density="0"
              rgba="1 0.423529 0.0392157 1" mesh="calf" />
            <geom size="0.125 0.0104 0.008" pos="0 0 -0.125" quat="0.707107 0 0.707107 0" type="box"
              rgba="1 0.423529 0.0392157 1" />
            <geom size="0.0165" pos="0 0 -0.25" contype="0" conaffinity="0" group="1" density="0"
              rgba="0 0.8 0 1" />
            <geom size="0.0265" pos="0 0 -0.25" rgba="0 0.8 0 1" />
          </body>
        </body>
      </body>
      <body name="RR_hip" pos="-0.2407 -0.051 0">
        <inertial pos="0.0206763 -0.0161444 -1.39762e-05" quat="0.412459 0.402465 0.58092 0.574831"
          mass="2.139" diaginertia="0.0043606 0.0043277 0.00233028" />
        <joint name="RR_hip_joint" pos="0 0 0" axis="1 0 0" range="-1.22173 1.22173"
          actuatorfrcrange="-35.278 35.278" />
        <geom quat="0 0 0 -1" type="mesh" contype="0" conaffinity="0" group="1" density="0"
          rgba="1 0.423529 0.0392157 1" mesh="hip" />
        <geom size="0.046 0.0209" pos="0 -0.083 0" quat="0.707107 0.707107 0 0" type="cylinder"
          rgba="1 0.423529 0.0392157 1" />
        <geom size="0.035 0.01" pos="0 -0.0298 0" quat="0.707107 0.707107 0 0" type="cylinder"
          contype="0" conaffinity="0" group="1" density="0" rgba="0 0.8 0 1" />
        <geom size="0.035 0.01" pos="0 -0.0298 0" quat="0.707107 0.707107 0 0" type="cylinder"
          rgba="0 0.8 0 1" />
        <body name="RR_thigh" pos="0 -0.0868 0">
          <inertial pos="-0.00464705 0.0202825 -0.039947"
            quat="0.994998 -0.0906147 0.0414285 -0.0071304" mass="0.771"
            diaginertia="0.00560787 0.004847 0.00135111" />
          <joint name="RR_thigh_joint" pos="0 0 0" axis="0 1 0" actuatorfrcrange="-35.278 35.278" />
          <geom type="mesh" contype="0" conaffinity="0" group="1" density="0"
            rgba="1 0.423529 0.0392157 1" mesh="thigh_mirror" />
          <geom size="0.125 0.0187 0.0215" pos="0 0 -0.125" quat="0.707107 0 0.707107 0" type="box"
            rgba="1 0.423529 0.0392157 1" />
          <!-- <geom size="0.035 0.01" pos="0 0.0997 0" quat="0.707107 0.707107 0 0" type="cylinder"
            contype="0" conaffinity="0" group="1" density="0" rgba="0 0.8 0 1" />
          <geom size="0.035 0.01" pos="0 0.0997 0" quat="0.707107 0.707107 0 0" type="cylinder"
            rgba="0 0.8 0 1" /> -->
          <body name="RR_calf" pos="0 0 -0.25">
            <inertial pos="0.00215606 4.88427e-05 -0.166671"
              quat="0.708049 0.000982931 0.00120829 0.706161" mass="0.267"
              diaginertia="0.00269606 0.00268354 5.47714e-05" />
            <joint name="RR_calf_joint" pos="0 0 0" axis="0 1 0" range="-2.77507 -0.645772"
              actuatorfrcrange="-44.4 44.4" />
            <geom type="mesh" contype="0" conaffinity="0" group="1" density="0"
              rgba="1 0.423529 0.0392157 1" mesh="calf" />
            <geom size="0.125 0.0104 0.008" pos="0 0 -0.125" quat="0.707107 0 0.707107 0" type="box"
              rgba="1 0.423529 0.0392157 1" />
            <geom size="0.0165" pos="0 0 -0.25" contype="0" conaffinity="0" group="1" density="0"
              rgba="0 0.8 0 1" />
            <geom size="0.0265" pos="0 0 -0.25" rgba="0 0.8 0 1" />
          </body>
        </body>
      </body>
      <body name="RL_hip" pos="-0.2407 0.051 0">
        <inertial pos="0.0206763 0.0161444 -1.39762e-05" quat="0.574831 0.58092 0.402465 0.412459"
          mass="2.139" diaginertia="0.0043606 0.0043277 0.00233028" />
        <joint name="RL_hip_joint" pos="0 0 0" axis="1 0 0" range="-1.22173 1.22173"
          actuatorfrcrange="-35.278 35.278" />
        <geom quat="0 0 1 0" type="mesh" contype="0" conaffinity="0" group="1" density="0"
          rgba="1 0.423529 0.0392157 1" mesh="hip" />
        <geom size="0.046 0.0209" pos="0 0.083 0" quat="0.707107 0.707107 0 0" type="cylinder"
          rgba="1 0.423529 0.0392157 1" />
        <geom size="0.035 0.01" pos="0 0.0298 0" quat="0.707107 0.707107 0 0" type="cylinder"
          contype="0" conaffinity="0" group="1" density="0" rgba="0 0.8 0 1" />
        <geom size="0.035 0.01" pos="0 0.0298 0" quat="0.707107 0.707107 0 0" type="cylinder"
          rgba="0 0.8 0 1" />
        <body name="RL_thigh" pos="0 0.0868 0">
          <inertial pos="-0.00464705 -0.0202825 -0.039947"
            quat="0.994998 0.0906147 0.0414285 0.0071304" mass="0.771"
            diaginertia="0.00560787 0.004847 0.00135111" />
          <joint name="RL_thigh_joint" pos="0 0 0" axis="0 1 0" actuatorfrcrange="-35.278 35.278" />
          <geom type="mesh" contype="0" conaffinity="0" group="1" density="0"
            rgba="1 0.423529 0.0392157 1" mesh="thigh" />
          <geom size="0.125 0.0187 0.0215" pos="0 0 -0.125" quat="0.707107 0 0.707107 0" type="box"
            rgba="1 0.423529 0.0392157 1" />
          <!-- <geom size="0.035 0.01" pos="0 -0.0997 0" quat="0.707107 0.707107 0 0" type="cylinder"
            contype="0" conaffinity="0" group="1" density="0" rgba="0 0.8 0 1" />
          <geom size="0.035 0.01" pos="0 -0.0997 0" quat="0.707107 0.707107 0 0" type="cylinder"
            rgba="0 0.8 0 1" /> -->
          <body name="RL_calf" pos="0 0 -0.25">
            <inertial pos="0.00215606 4.88427e-05 -0.166671"
              quat="0.708049 0.000982931 0.00120829 0.706161" mass="0.267"
              diaginertia="0.00269606 0.00268354 5.47714e-05" />
            <joint name="RL_calf_joint" pos="0 0 0" axis="0 1 0" range="-2.77507 -0.645772"
              actuatorfrcrange="-44.4 44.4" />
            <geom type="mesh" contype="0" conaffinity="0" group="1" density="0"
              rgba="1 0.423529 0.0392157 1" mesh="calf" />
            <geom size="0.125 0.0104 0.008" pos="0 0 -0.125" quat="0.707107 0 0.707107 0" type="box"
              rgba="1 0.423529 0.0392157 1" />
            <geom size="0.0165" pos="0 0 -0.25" contype="0" conaffinity="0" group="1" density="0"
              rgba="0 0.8 0 1" />
            <geom size="0.0265" pos="0 0 -0.25" rgba="0 0.8 0 1" />
          </body>
        </body>
      </body>

    </body>
  </worldbody>
  <actuator>
    <!-- Front Right Leg (FR) -->
    <motor name="FR_hip_joint" joint="FR_hip_joint" gear="1" ctrllimited="true" ctrlrange="-200 200" />
    <motor name="FR_thigh_joint" joint="FR_thigh_joint" gear="1" ctrllimited="true"
      ctrlrange="-200 200" />
    <motor name="FR_calf_joint" joint="FR_calf_joint" gear="1" ctrllimited="true"
      ctrlrange="-200 200" />

    <!-- Front Left Leg (FL) -->
    <motor name="FL_hip_joint" joint="FL_hip_joint" gear="1" ctrllimited="true" ctrlrange="-200 200" />
    <motor name="FL_thigh_joint" joint="FL_thigh_joint" gear="1" ctrllimited="true"
      ctrlrange="-200 200" />
    <motor name="FL_calf_joint" joint="FL_calf_joint" gear="1" ctrllimited="true"
      ctrlrange="-200 200" />

    <!-- Rear Right Leg (RR) -->
    <motor name="RR_hip_joint" joint="RR_hip_joint" gear="1" ctrllimited="true" ctrlrange="-200 200" />
    <motor name="RR_thigh_joint" joint="RR_thigh_joint" gear="1" ctrllimited="true"
      ctrlrange="-200 200" />
    <motor name="RR_calf_joint" joint="RR_calf_joint" gear="1" ctrllimited="true"
      ctrlrange="-200 200" />

    <!-- Rear Left Leg (RL) -->
    <motor name="RL_hip_joint" joint="RL_hip_joint" gear="1" ctrllimited="true" ctrlrange="-200 200" />
    <motor name="RL_thigh_joint" joint="RL_thigh_joint" gear="1" ctrllimited="true"
      ctrlrange="-200 200" />
    <motor name="RL_calf_joint" joint="RL_calf_joint" gear="1" ctrllimited="true"
      ctrlrange="-200 200" />

      <!-- Arm -->
      <motor name="arm_joint1" joint="arm_joint1" gear="1" ctrllimited="true" ctrlrange="-200 200" />
      <motor name="arm_joint2" joint="arm_joint2" gear="1" ctrllimited="true" ctrlrange="-200 200" />
      <motor name="arm_joint3" joint="arm_joint3" gear="1" ctrllimited="true" ctrlrange="-200 200" />
      <motor name="arm_joint4" joint="arm_joint4" gear="1" ctrllimited="true" ctrlrange="-200 200" />
      <motor name="arm_joint5" joint="arm_joint5" gear="1" ctrllimited="true" ctrlrange="-200 200" />
  </actuator>

  <sensor>
    <framequat name='orientation' objtype='site' objname='imu' />
    <!-- <framepos     name='position' objtype='site' objname='imu'/> -->
    <!-- <gyro          name='angular-velocity'    site='imu' cutoff='34.9'/> -->
    <!-- <velocimeter   name='linear-velocity'     site='imu' cutoff='30'/> -->
    <!-- <accelerometer name='linear-acceleration' site='imu' cutoff='157'/> -->
    <!-- <magnetometer  name='magnetometer'        site='imu'/> -->
  </sensor>
</mujoco>