<mujoco model="orca_ndescription">
  <compiler angle="radian" meshdir="../meshes/"/>
  <option timestep="0.001" iterations='50' solver='PGS' gravity='0 0 -9.81'/>

  <default>
    <joint limited='true'/>
    <motor ctrllimited='true'/>
    <equality solref='0.001 2'/>
    
    <default class="motor_joint">
      <joint damping="1.0" limited="true" armature="0.01"/>
    </default>
  </default>

  <asset>
    <mesh name="base_link" file="base_link.STL"/>
    <mesh name="base_link_cls" file="base_link_cls.STL"/>
    <mesh name="larm_link1" file="larm_link1.STL"/>
    <mesh name="larm_link1_cls" file="larm_link1_cls.STL"/>
    <mesh name="larm_link2" file="larm_link2.STL"/>
    <mesh name="larm_link2_cls" file="larm_link2_cls.STL"/>
    <mesh name="larm_link3" file="larm_link3.STL"/>
    <mesh name="larm_link3_cls" file="larm_link3_cls.STL"/>
    <mesh name="larm_link4" file="larm_link4.STL"/>
    <mesh name="larm_link4_cls" file="larm_link4_cls.STL"/>
    <mesh name="larm_link5" file="larm_link5.STL"/>
    <mesh name="larm_link5_cls" file="larm_link5_cls.STL"/>
    <mesh name="larm_link6" file="larm_link6.STL"/>
    <mesh name="larm_link6_cls" file="larm_link6_cls.STL"/>
    <mesh name="rarm_link1" file="rarm_link1.STL"/>
    <mesh name="rarm_link1_cls" file="rarm_link1_cls.STL"/>
    <mesh name="rarm_link2" file="rarm_link2.STL"/>
    <mesh name="rarm_link2_cls" file="rarm_link2_cls.STL"/>
    <mesh name="rarm_link3" file="rarm_link3.STL"/>
    <mesh name="rarm_link3_cls" file="rarm_link3_cls.STL"/>
    <mesh name="rarm_link4" file="rarm_link4.STL"/>
    <mesh name="rarm_link4_cls" file="rarm_link4_cls.STL"/>
    <mesh name="rarm_link5" file="rarm_link5.STL"/>
    <mesh name="rarm_link5_cls" file="rarm_link5_cls.STL"/>
    <mesh name="rarm_link6" file="rarm_link6.STL"/>
    <mesh name="rarm_link6_cls" file="rarm_link6_cls.STL"/>
    <mesh name="head_link1" file="head_link1.STL"/>
    <mesh name="head_link1_cls" file="head_link1_cls.STL"/>
    <mesh name="head_link2" file="head_link2.STL"/>
    <mesh name="head_link2_cls" file="head_link2_cls.STL"/>
    <mesh name="head_link3" file="head_link3.STL"/>
    <mesh name="head_link3_cls" file="head_link3_cls.STL"/>
    <mesh name="trunk_link1" file="trunk_link1.STL"/>
    <mesh name="trunk_link1_cls" file="trunk_link1_cls.STL"/>
    <mesh name="lleg_link1" file="lleg_link1.STL"/>
    <mesh name="lleg_link1_cls" file="lleg_link1_cls.STL"/>
    <mesh name="lleg_link2" file="lleg_link2.STL"/>
    <mesh name="lleg_link2_cls" file="lleg_link2_cls.STL"/>
    <mesh name="lleg_link3" file="lleg_link3.STL"/>
    <mesh name="lleg_link3_cls" file="lleg_link3_cls.STL"/>
    <mesh name="lleg_link4" file="lleg_link4.STL"/>
    <mesh name="lleg_link4_cls" file="lleg_link4_cls.STL"/>
    <mesh name="lleg_link5" file="lleg_link5.STL"/>
    <mesh name="lleg_link5_cls" file="lleg_link5_cls.STL"/>
    <mesh name="lleg_link6" file="lleg_link6.STL"/>
    <mesh name="lleg_link6_cls" file="lleg_link6_cls.STL"/>
    <mesh name="rleg_link1" file="rleg_link1.STL"/>
    <mesh name="rleg_link1_cls" file="rleg_link1_cls.STL"/>
    <mesh name="rleg_link2" file="rleg_link2.STL"/>
    <mesh name="rleg_link2_cls" file="rleg_link2_cls.STL"/>
    <mesh name="rleg_link3" file="rleg_link3.STL"/>
    <mesh name="rleg_link3_cls" file="rleg_link3_cls.STL"/>
    <mesh name="rleg_link4" file="rleg_link4.STL"/>
    <mesh name="rleg_link4_cls" file="rleg_link4_cls.STL"/>
    <mesh name="rleg_link5" file="rleg_link5.STL"/>
    <mesh name="rleg_link5_cls" file="rleg_link5_cls.STL"/>
    <mesh name="rleg_link6" file="rleg_link6.STL"/>
    <mesh name="rleg_link6_cls" file="rleg_link6_cls.STL"/>

    <texture name="texplane" type="2d" builtin="checker" rgb1=".2 .3 .4" rgb2=".1 0.15 0.2"
        width="512" height="512" mark="cross" markrgb=".8 .8 .8"/>
    <material name="matplane" reflectance="0." texture="texplane" texrepeat="1 1" texuniform="true"/>
  </asset>

  <worldbody>
    <light directional="true" diffuse=".4 .4 .4" specular="0.1 0.1 0.1" pos="0 0 5.0" dir="0 0 -1" castshadow="false"/>
    <light directional="true" diffuse=".6 .6 .6" specular="0.2 0.2 0.2" pos="0 0 4" dir="0 0 -1"/>
    <geom name="ground" type="plane" size="0 0 1" pos="0.001 0 -1" quat="1 0 0 0" material="matplane" condim="1" conaffinity='15'/>

    <body name="base_link" pos="0.0 0.0 -0.05">
      <inertial pos="-0.000228684 -2.46E-05 0.195013197" mass="11.03319241" diaginertia="0.179385252 0.155358264 0.065422946" />
      <joint type='slide' axis='1 0 0' limited='false' />
      <joint type='slide' axis='0 1 0' limited='false' />
      <joint type='slide' axis='0 0 1' limited='false' />
      <joint type='ball' limited='false' />
      <site name='imu' size='0.01' pos='0.0 0 0.0'/>

      <geom size="0.0005 0.0005 0.0005" type="box" contype="0" conaffinity="0" group="1" density="0"/>
      <geom type="mesh" contype="0" conaffinity="0" group="1" density="0" rgba="1 1 1 1" mesh="base_link"/>
      <geom quat="-2.59708e-06 0.707035 0.707179 -2.59761e-06" type="mesh" rgba="1 1 1 1" mesh="base_link_cls"/>
      <body name="larm_link1" pos="0 0.13495 0.29591" quat="0.996195 0.0871543 0 0">
        <inertial pos="0.000439855 0.0358502 7.91e-06" quat="0.519328 0.479105 -0.519788 0.480185" mass="0.576081" diaginertia="0.00059525 0.000527291 0.000441012"/>
        <joint name="larm_joint1" pos="0 0 0" axis="0 1 0" range="-2.88 2.88" actuatorfrcrange="-94 94" damping="0.2"/>
        <geom type="mesh" contype="0" conaffinity="0" group="1" density="0" rgba="1 1 1 1" mesh="larm_link1"/>
        <geom quat="0.707035 -0.707179 0 0" type="mesh" rgba="1 1 1 1" mesh="larm_link1_cls"/>
        <body name="larm_link2" pos="-0.0015 0.0499987 0" quat="0.454519 -0.541675 -0.541675 -0.454519">
          <inertial pos="-0.0256333 0.000250778 0.0157168" quat="0.546056 0.647986 -0.337561 0.409864" mass="0.235909" diaginertia="0.000523812 0.000383492 0.000280485"/>
          <joint name="larm_joint2" pos="0 0 0" axis="0 1 0" range="-0.17 2.62" actuatorfrcrange="-36 36" damping="0.2"/>
          <geom type="mesh" contype="0" conaffinity="0" group="1" density="0" rgba="1 1 1 1" mesh="larm_link2"/>
          <geom quat="0.499898 -0.5 -0.5 -0.500102" type="mesh" rgba="1 1 1 1" mesh="larm_link2_cls"/>
          <body name="larm_link3" pos="-0.0645 0 0.020001" quat="0.707105 0 0 0.707108">
            <inertial pos="0.000500131 0.0897007 0.00308625" quat="0.67552 0.737342 0.000778581 -0.000328019" mass="1.08737" diaginertia="0.00248891 0.00232032 0.000710521"/>
            <joint name="larm_joint3" pos="0 0 0" axis="0 1 0" range="-2.79 2.79" actuatorfrcrange="-36 36" damping="1"/>
            <geom type="mesh" contype="0" conaffinity="0" group="1" density="0" rgba="1 1 1 1" mesh="larm_link3"/>
            <geom quat="0.499898 -0.5 -0.5 -0.500102" type="mesh" rgba="1 1 1 1" mesh="larm_link3_cls"/>
            <body name="larm_link4" pos="0 0.1835 0" quat="0.707107 0.707107 0 0">
              <inertial pos="0.00191171 0.0101619 -0.056078" quat="0.944356 -0.152014 0.023265 0.29076" mass="0.63159" diaginertia="0.00143401 0.00142131 0.000920924"/>
              <joint name="larm_joint4" pos="0 0 0" axis="0 1 0" range="-1.57 1.57" actuatorfrcrange="-36 36" damping="1"/>
              <geom type="mesh" contype="0" conaffinity="0" group="1" density="0" rgba="1 1 1 1" mesh="larm_link4"/>
              <geom quat="0.707035 0.707179 0 0" type="mesh" rgba="1 1 1 1" mesh="larm_link4_cls"/>
              <body name="larm_link5" pos="0 0 -0.075" quat="0.5 -0.5 -0.5 -0.5">
                <inertial pos="-0.0731591 0.00618732 3.44e-06" quat="-0.109346 0.691581 0.147622 0.698547" mass="0.451979" diaginertia="0.000579673 0.000574394 0.000224843"/>
                <joint name="larm_joint5" pos="0 0 0" axis="0 1 0" range="-1.57 0.35" actuatorfrcrange="-36 36" damping="1"/>
                <geom type="mesh" contype="0" conaffinity="0" group="1" density="0" rgba="1 1 1 1" mesh="larm_link5"/>
                <geom quat="0.499898 -0.5 -0.5 -0.500102" type="mesh" rgba="1 1 1 1" mesh="larm_link5_cls"/>
                <body name="larm_link6" pos="-0.105 0 0" quat="0.499998 0.5 -0.5 0.500002">
                  <inertial pos="0.000892339 0.105968 3.11e-05" quat="0.707253 0.70692 0.00503905 0.00567331" mass="0.830189" diaginertia="0.0023087 0.00201411 0.000612016"/>
                  <!-- <joint name="larm_joint6" pos="0 0 0" axis="0 1 0" range="-2.79 2.79" actuatorfrcrange="-36 36" damping="0.2"/> -->
                  <geom type="mesh" contype="0" conaffinity="0" group="1" density="0" rgba="1 1 1 1" mesh="larm_link6"/>
                  <geom type="mesh" rgba="1 1 1 1" mesh="larm_link6_cls"/>
                </body>
              </body>
            </body>
          </body>
        </body>
      </body>
      <body name="rarm_link1" pos="0 -0.134953 0.295908" quat="0.996195 -0.0871557 0 0">
        <inertial pos="0.000439873 -0.0358502 7.93e-06" quat="0.479106 0.519329 -0.480184 0.519787" mass="0.576081" diaginertia="0.000595249 0.000527291 0.000441012"/>
        <joint name="rarm_joint1" pos="0 0 0" axis="0 1 0" range="-2.88 2.88" actuatorfrcrange="-94 94" damping="0.2"/>
        <geom type="mesh" contype="0" conaffinity="0" group="1" density="0" rgba="1 1 1 1" mesh="rarm_link1"/>
        <geom quat="0.707035 0.707179 0 0" type="mesh" rgba="1 1 1 1" mesh="rarm_link1_cls"/>
        <body name="rarm_link2" pos="-0.0015 -0.0499987 0" quat="0.541675 -0.454519 -0.454519 -0.541675">
          <inertial pos="-0.0256309 0.000253501 -0.015721" quat="0.337573 0.409864 -0.546117 0.64793" mass="0.235939" diaginertia="0.000523817 0.000383486 0.000280446"/>
          <joint name="rarm_joint2" pos="0 0 0" axis="0 -1 0" range="-0.17 2.62" actuatorfrcrange="-36 36" damping="0.2"/>
          <geom type="mesh" contype="0" conaffinity="0" group="1" density="0" rgba="1 1 1 1" mesh="rarm_link2"/>
          <geom quat="0.499898 -0.5 -0.5 -0.500102" type="mesh" rgba="1 1 1 1" mesh="rarm_link2_cls"/>
          <body name="rarm_link3" pos="-0.0645 0 -0.0200014" quat="0.707107 0 0 0.707107">
            <inertial pos="0.000500342 0.0897013 -0.00308666" quat="0.737338 0.675524 -0.000289164 0.000745159" mass="1.08737" diaginertia="0.00248889 0.00232032 0.000710539"/>
            <joint name="rarm_joint3" pos="0 0 0" axis="0 1 0" range="-2.79 2.79" actuatorfrcrange="-36 36" damping="1"/>
            <geom type="mesh" contype="0" conaffinity="0" group="1" density="0" rgba="1 1 1 1" mesh="rarm_link3"/>
            <geom quat="0.499898 -0.5 -0.5 -0.500102" type="mesh" rgba="1 1 1 1" mesh="rarm_link3_cls"/>
            <body name="rarm_link4" pos="0 0.1835 0" quat="0.707107 0.707107 0 0">
              <inertial pos="0.00190835 -0.0101584 -0.0560802" quat="0.944512 0.152026 0.023182 -0.290255" mass="0.63162" diaginertia="0.00143403 0.00142132 0.000920982"/>
              <joint name="rarm_joint4" pos="0 0 0" axis="0 1 0" range="-1.57 1.57" actuatorfrcrange="-36 36" damping="1"/>
              <geom type="mesh" contype="0" conaffinity="0" group="1" density="0" rgba="1 1 1 1" mesh="rarm_link4"/>
              <geom quat="0.707035 0.707179 0 0" type="mesh" rgba="1 1 1 1" mesh="rarm_link4_cls"/>
              <body name="rarm_link5" pos="0 0 -0.075" quat="0.5 -0.5 -0.5 -0.5">
                <inertial pos="-0.0731591 0.00618737 -3.6e-06" quat="-0.147696 0.698558 0.109271 0.691565" mass="0.451978" diaginertia="0.000579673 0.000574398 0.00022484"/>
                <joint name="rarm_joint5" pos="0 0 0" axis="0 1 0" range="-0.35 1.57" actuatorfrcrange="-36 36" damping="1"/>
                <geom type="mesh" contype="0" conaffinity="0" group="1" density="0" rgba="1 1 1 1" mesh="rarm_link5"/>
                <geom quat="0.499898 -0.5 -0.5 -0.500102" type="mesh" rgba="1 1 1 1" mesh="rarm_link5_cls"/>
                <body name="rarm_link6" pos="-0.105 0 0" quat="0.5 0.5 -0.5 0.5">
                  <inertial pos="-0.000892336 0.105968 3.1e-05" quat="0.707253 0.70692 -0.00503907 -0.00567328" mass="0.830188" diaginertia="0.0023087 0.00201411 0.000612016"/>
                  <!-- <joint name="rarm_joint6" pos="0 0 0" axis="0 1 0" range="-2.79 2.79" actuatorfrcrange="-36 36" damping="0.2"/> -->
                  <geom type="mesh" contype="0" conaffinity="0" group="1" density="0" rgba="1 1 1 1" mesh="rarm_link6"/>
                  <geom type="mesh" rgba="1 1 1 1" mesh="rarm_link6_cls"/>
                </body>
              </body>
            </body>
          </body>
        </body>
      </body>
      <body name="head_link1" pos="0.0086 0 0.4656" quat="0.707035 0 0.707179 0">
        <inertial pos="0 0 0" mass="0.000534071" diaginertia="5.34e-09 5.34e-09 5.34e-09"/>
        <!-- <joint name="head_roll_joint" pos="0 0 0" axis="0 0 1" range="-0.349 0.349" actuatorfrcrange="-3 3" damping="0.2"/> -->
        <geom type="mesh" contype="0" conaffinity="0" group="1" density="0" rgba="1 1 1 1" mesh="head_link1"/>
        <geom type="mesh" rgba="1 1 1 1" mesh="head_link1_cls"/>
        <body name="head_link2" quat="0.5 -0.500002 0.499998 0.5">
          <inertial pos="0 0 0" mass="0.000534071" diaginertia="5.34e-09 5.34e-09 5.34e-09"/>
          <!-- <joint name="head_pitch_joint" pos="0 0 0" axis="0 0 1" range="-0.523 0.349" actuatorfrcrange="-3 3" damping="0.2"/> -->
          <geom type="mesh" contype="0" conaffinity="0" group="1" density="0" rgba="1 1 1 1" mesh="head_link2"/>
          <geom type="mesh" rgba="1 1 1 1" mesh="head_link2_cls"/>
          <body name="head_link3" quat="-2.59734e-06 2.59735e-06 0.707108 -0.707105">
            <inertial pos="-0.000672526 -8.45e-05 0.0452592" quat="0.528315 0.528245 -0.469943 0.470099" mass="0.960824" diaginertia="0.00480572 0.00459539 0.00222606"/>
            <!-- <joint name="head_yaw_joint" pos="0 0 0" axis="0 0 1" range="-1.57 1.57" actuatorfrcrange="-3 3" damping="0.2"/> -->
            <geom type="mesh" contype="0" conaffinity="0" group="1" density="0" rgba="1 1 1 1" mesh="head_link3"/>
            <geom type="mesh" rgba="1 1 1 1" mesh="head_link3_cls"/>
          </body>
        </body>
      </body>
      <body name="waist_yaw_link">
        <inertial pos="-8.47e-05 -9.16e-08 -0.06848" quat="0.505558 0.50296 -0.497051 0.494351" mass="3.8853" diaginertia="0.0147602 0.0141828 0.0138"/>
        <joint name="waist_yaw_joint" pos="0 0 0" axis="0 0 1" range="-1.571 1.571" actuatorfrcrange="-36 36" damping="0.2"/>
        <geom type="mesh" contype="0" conaffinity="0" group="1" density="0" rgba="1 1 1 1" mesh="trunk_link1"/>
        <geom pos="0 0 -0.078" quat="1.34924e-11 -3.67321e-06 -3.67321e-06 -1" type="mesh" rgba="1 1 1 1" mesh="trunk_link1_cls"/>
        <body name="lleg_link1" pos="0 0.095 -0.078">
          <inertial pos="-0.04615 -0.00057339 -0.10138" quat="0.606771 0.340532 0.305343 0.650102" mass="1.7192" diaginertia="0.0116346 0.010204 0.00377219"/>
          <joint name="lleg_joint1" pos="0 0 0" axis="0 -1 0" range="-1.22 1.92" actuatorfrcrange="-150 150" damping="0.2"/>
          <geom type="mesh" contype="0" conaffinity="0" group="1" density="0" rgba="1 1 1 1" mesh="lleg_link1"/>
          <!-- <geom quat="0.707035 -0.707179 0 0" type="mesh" rgba="1 1 1 1" mesh="lleg_link1_cls"/> -->
          <body name="lleg_link2" pos="0 0 -0.1415" quat="0.5 -0.5 -0.5 -0.5">
            <inertial pos="-0.00695412 -0.00602969 5.86e-06" quat="0.698555 0.715384 0.0120792 0.0100686" mass="1.30043" diaginertia="0.00295589 0.00228715 0.00165543"/>
            <joint name="lleg_joint2" pos="0 0 0" axis="0 -1 0" range="-1.57 0.07" actuatorfrcrange="-94 94" damping="0.2"/>
            <geom type="mesh" contype="0" conaffinity="0" group="1" density="0" rgba="1 1 1 1" mesh="lleg_link2"/>
            <!-- <geom type="mesh" rgba="1 1 1 1" mesh="lleg_link2_cls"/> -->
            <body name="lleg_link3" pos="-0.0275 0 0" quat="0.707107 0 0 0.707107">
              <inertial pos="-0.00319346 0.118677 0.0116288" quat="0.608127 0.462735 -0.465437 0.446571" mass="3.18617" diaginertia="0.0187932 0.0182038 0.00732765"/>
              <joint name="lleg_joint3" pos="0 0 0" axis="0 1 0" range="-2.6 0.44" actuatorfrcrange="-94 94" damping="1"/>
              <geom type="mesh" contype="0" conaffinity="0" group="1" density="0" rgba="1 1 1 1" mesh="lleg_link3"/>
              <geom quat="0.707035 -0.707179 0 0" type="mesh" rgba="1 1 1 1" mesh="lleg_link3_cls"/>
              <body name="lleg_link4" pos="0 0.267722 0" quat="0.707107 0.707107 0 0">
                <inertial pos="0.00351609 -0.00641438 -0.108165" quat="0.593832 0.00846286 0.00230272 0.804542" mass="1.41173" diaginertia="0.0101633 0.0100957 0.00106518"/>
                <joint name="lleg_joint4" pos="0 0 0" axis="0 -1 0" range="-2.4 0.1" actuatorfrcrange="-150 150" damping="1"/>
                <geom type="mesh" contype="0" conaffinity="0" group="1" density="0" rgba="1 1 1 1" mesh="lleg_link4"/>
                <geom quat="0.707035 0.707179 0 0" type="mesh" rgba="1 1 1 1" mesh="lleg_link4_cls"/>
                <body name="lleg_link5" pos="0 -0.009 -0.28">
                  <inertial pos="0.021822 4.91e-06 -0.0148754" quat="0.000357289 0.733908 0.000589571 0.679248" mass="0.561438" diaginertia="0.000845723 0.000806268 0.000283479"/>
                  <joint name="lleg_joint5" pos="0 0 0" axis="0 -1 0" range="-0.56 0.45" actuatorfrcrange="-36 36" damping="1"/>
                  <geom type="mesh" contype="0" conaffinity="0" group="1" density="0" rgba="1 1 1 1" mesh="lleg_link5"/>
                  <geom quat="0.707035 0.707179 0 0" type="mesh" rgba="1 1 1 1" mesh="lleg_link5_cls"/>
                  <body name="lleg_link6" pos="0 0 -0.016">
                    <inertial pos="0.0231941 -0.000318257 -0.0309056" quat="0.015808 0.710289 0.00142222 0.703732" mass="0.37315" diaginertia="0.00150819 0.00138024 0.00036124"/>
                    <joint name="lleg_joint6" pos="0 0 0" axis="1 0 0" range="-0.52 0.52" actuatorfrcrange="-36 36" damping="1"/>
                    <geom type="mesh" contype="0" conaffinity="0" group="1" density="0" rgba="1 1 1 1" mesh="lleg_link6"/>
                    <geom quat="-2.59708e-06 -0.707179 -2.59761e-06 0.707035" type="mesh" rgba="1 1 1 1" mesh="lleg_link6_cls"/>
                    <!-- <geom size="0.001" contype="0" conaffinity="0" group="1" density="0"/>
                    <geom size="0.005"/>
                    <geom size="0.001" pos="0.12 0 -0.04" contype="0" conaffinity="0" group="1" density="0"/>
                    <geom size="0.005" pos="0.12 0 -0.04"/>
                    <geom size="0.001" pos="-0.07 0 -0.04" contype="0" conaffinity="0" group="1" density="0"/>
                    <geom size="0.005" pos="-0.07 0 -0.04"/> -->
                  </body>
                </body>
              </body>
            </body>
          </body>
        </body>
        <body name="rleg_link1" pos="0 -0.095 -0.078">
          <inertial pos="-0.04615 0.00057345 -0.10138" quat="0.650088 0.305351 0.340521 0.606789" mass="1.7192" diaginertia="0.0116356 0.0102041 0.00377225"/>
          <joint name="rleg_joint1" pos="0 0 0" axis="0 -1 0" range="-1.22 1.92" actuatorfrcrange="-150 150" damping="0.2"/>
          <geom type="mesh" contype="0" conaffinity="0" group="1" density="0" rgba="1 1 1 1" mesh="rleg_link1"/>
          <!-- <geom quat="-2.59708e-06 -2.59761e-06 0.707035 -0.707179" type="mesh" rgba="1 1 1 1" mesh="rleg_link1_cls"/> -->
          <body name="rleg_link2" pos="-0.0098871 0 -0.1545" quat="0.499998 -0.5 -0.5 -0.500002">
            <inertial pos="0.006046 0.0038573 -5.86e-06" quat="0.715383 0.698556 0.0100366 0.0120559" mass="1.3004" diaginertia="0.00295587 0.00228715 0.00165537"/>
            <joint name="rleg_joint2" pos="0 0 0" axis="0 1 0" range="-1.57 0.07" actuatorfrcrange="-94 94" damping="0.2"/>
            <geom type="mesh" contype="0" conaffinity="0" group="1" density="0" rgba="1 1 1 1" mesh="rleg_link2"/>
            <!-- <geom quat="-3.67321e-06 0 1 0" type="mesh" rgba="1 1 1 1" mesh="rleg_link2_cls"/> -->
            <body name="rleg_link3" pos="-0.0145 0.0098871 0" quat="0.707105 0 0 0.707108">
              <inertial pos="-0.00319389 0.118678 -0.0116297" quat="0.465451 0.446606 -0.608101 0.462722" mass="3.18629" diaginertia="0.0187938 0.0182042 0.00732793"/>
              <joint name="rleg_joint3" pos="0 0 0" axis="0 -1 0" range="-2.6 0.44" actuatorfrcrange="-94 94" damping="1"/>
              <geom type="mesh" contype="0" conaffinity="0" group="1" density="0" rgba="1 1 1 1" mesh="rleg_link3"/>
              <geom quat="-2.59708e-06 2.59761e-06 0.707035 0.707179" type="mesh" rgba="1 1 1 1" mesh="rleg_link3_cls"/>
              <body name="rleg_link4" pos="0 0.26772 0" quat="0.707105 0.707108 0 0">
                <inertial pos="0.00351605 0.00641396 -0.108166" quat="0.804557 0.00230217 0.00846234 0.593811" mass="1.41172" diaginertia="0.0101636 0.0100959 0.00106517"/>
                <joint name="rleg_joint4" pos="0 0 0" axis="0 -1 0" range="-2.4 0.1" actuatorfrcrange="-150 150" damping="1"/>
                <geom type="mesh" contype="0" conaffinity="0" group="1" density="0" rgba="1 1 1 1" mesh="rleg_link4"/>
                <geom quat="-2.59708e-06 -2.59761e-06 0.707179 0.707035" type="mesh" rgba="1 1 1 1" mesh="rleg_link4_cls"/>
                <body name="rleg_link5" pos="0 0.009 -0.28">
                  <inertial pos="0.021822 -4.46e-06 -0.014875" quat="-0.000378773 0.733909 -0.000610222 0.679247" mass="0.56144" diaginertia="0.000845715 0.00080626 0.000283485"/>
                  <joint name="rleg_joint5" pos="0 0 0" axis="0 -1 0" range="-0.56 0.45" actuatorfrcrange="-36 36" damping="1"/>
                  <geom type="mesh" contype="0" conaffinity="0" group="1" density="0" rgba="1 1 1 1" mesh="rleg_link5"/>
                  <geom quat="-2.59708e-06 -2.59761e-06 0.707179 0.707035" type="mesh" rgba="1 1 1 1" mesh="rleg_link5_cls"/>
                  <body name="rleg_link6" pos="0 0 -0.016">
                    <inertial pos="0.0231929 0.000320242 -0.0309028" quat="-0.0158595 0.710294 -0.00147409 0.703725" mass="0.373172" diaginertia="0.00150818 0.00138017 0.000361174"/>
                    <joint name="rleg_joint6" pos="0 0 0" axis="1 0 0" range="-0.52 0.52" actuatorfrcrange="-36 36" damping="1"/>
                    <geom type="mesh" contype="0" conaffinity="0" group="1" density="0" rgba="1 1 1 1" mesh="rleg_link6"/>
                    <geom quat="-0.707179 -5.1947e-06 0.707035 -5.1947e-06" type="mesh" rgba="1 1 1 1" mesh="rleg_link6_cls"/>
                    <!-- <geom size="0.001" pos="0.12 0 -0.04" contype="0" conaffinity="0" group="1" density="0"/> -->
                    <!-- <geom size="0.005" pos="0.12 0 -0.04"/> -->
                    <!-- <geom size="0.001" contype="0" conaffinity="0" group="1" density="0"/> -->
                    <!-- <geom size="0.005"/> -->
                    <!-- <geom size="0.001" pos="-0.07 0 -0.04" contype="0" conaffinity="0" group="1" density="0"/> -->
                    <!-- <geom size="0.005" pos="-0.07 0 -0.04"/> -->
                  </body>
                </body>
              </body>
            </body>
          </body>
        </body>
      </body>
    </body>
  </worldbody>

  <actuator>
    
    <!-- <motor name="waist_yaw_joint" joint="waist_yaw_joint" gear="1" ctrllimited="true" ctrlrange="-200 200"/>
    <motor name="lleg_joint1" joint="lleg_joint1" gear="1" ctrllimited="true" ctrlrange="-200 200"/>
    <motor name="rleg_joint1" joint="rleg_joint1" gear="1" ctrllimited="true" ctrlrange="-200 200"/>
    <motor name="lleg_joint2" joint="lleg_joint2" gear="1" ctrllimited="true" ctrlrange="-200 200"/>
    <motor name="rleg_joint2" joint="rleg_joint2" gear="1" ctrllimited="true" ctrlrange="-200 200"/>
    <motor name="larm_joint1" joint="larm_joint1" gear="1" ctrllimited="true" ctrlrange="-200 200"/>
    <motor name="rarm_joint1" joint="rarm_joint1" gear="1" ctrllimited="true" ctrlrange="-200 200"/>
    <motor name="lleg_joint3" joint="lleg_joint3" gear="1" ctrllimited="true" ctrlrange="-200 200"/>
    <motor name="rleg_joint3" joint="rleg_joint3" gear="1" ctrllimited="true" ctrlrange="-200 200"/>
    <motor name="larm_joint2" joint="larm_joint2" gear="1" ctrllimited="true" ctrlrange="-200 200"/>
    <motor name="rarm_joint2" joint="rarm_joint2" gear="1" ctrllimited="true" ctrlrange="-200 200"/>
    <motor name="lleg_joint4" joint="lleg_joint4" gear="1" ctrllimited="true" ctrlrange="-200 200"/>
    <motor name="rleg_joint4" joint="rleg_joint4" gear="1" ctrllimited="true" ctrlrange="-200 200"/>
    <motor name="larm_joint3" joint="larm_joint3" gear="1" ctrllimited="true" ctrlrange="-200 200"/>
    <motor name="rarm_joint3" joint="rarm_joint3" gear="1" ctrllimited="true" ctrlrange="-200 200"/>
    <motor name="lleg_joint5" joint="lleg_joint5" gear="1" ctrllimited="true" ctrlrange="-200 200"/>
    <motor name="rleg_joint5" joint="rleg_joint5" gear="1" ctrllimited="true" ctrlrange="-200 200"/>
    <motor name="larm_joint4" joint="larm_joint4" gear="1" ctrllimited="true" ctrlrange="-200 200"/>
    <motor name="rarm_joint4" joint="rarm_joint4" gear="1" ctrllimited="true" ctrlrange="-200 200"/>
    <motor name="lleg_joint6" joint="lleg_joint6" gear="1" ctrllimited="true" ctrlrange="-200 200"/>
    <motor name="rleg_joint6" joint="rleg_joint6" gear="1" ctrllimited="true" ctrlrange="-200 200"/>
    <motor name="larm_joint5" joint="larm_joint5" gear="1" ctrllimited="true" ctrlrange="-200 200"/>
    <motor name="rarm_joint5" joint="rarm_joint5" gear="1" ctrllimited="true" ctrlrange="-200 200"/>
    <motor name="larm_joint6" joint="larm_joint6" gear="1" ctrllimited="true" ctrlrange="-200 200"/>
    <motor name="rarm_joint6" joint="rarm_joint6" gear="1" ctrllimited="true" ctrlrange="-200 200"/> -->

    <!-- in the same order with the joints in the worldbody -->
    <motor name="larm_joint1" joint="larm_joint1" gear="1" ctrllimited="true" ctrlrange="-200 200"/>
    <motor name="larm_joint2" joint="larm_joint2" gear="1" ctrllimited="true" ctrlrange="-200 200"/>
    <motor name="larm_joint3" joint="larm_joint3" gear="1" ctrllimited="true" ctrlrange="-200 200"/>
    <motor name="larm_joint4" joint="larm_joint4" gear="1" ctrllimited="true" ctrlrange="-200 200"/>
    <motor name="larm_joint5" joint="larm_joint5" gear="1" ctrllimited="true" ctrlrange="-200 200"/>
    <!-- <motor name="larm_joint6" joint="larm_joint6" gear="1" ctrllimited="true" ctrlrange="-200 200"/> -->
    <motor name="rarm_joint1" joint="rarm_joint1" gear="1" ctrllimited="true" ctrlrange="-200 200"/>
    <motor name="rarm_joint2" joint="rarm_joint2" gear="1" ctrllimited="true" ctrlrange="-200 200"/>
    <motor name="rarm_joint3" joint="rarm_joint3" gear="1" ctrllimited="true" ctrlrange="-200 200"/>
    <motor name="rarm_joint4" joint="rarm_joint4" gear="1" ctrllimited="true" ctrlrange="-200 200"/>
    <motor name="rarm_joint5" joint="rarm_joint5" gear="1" ctrllimited="true" ctrlrange="-200 200"/>
    <!-- <motor name="rarm_joint6" joint="rarm_joint6" gear="1" ctrllimited="true" ctrlrange="-200 200"/> -->
    
    <motor name="waist_yaw_joint" joint="waist_yaw_joint" gear="1" ctrllimited="true" ctrlrange="-200 200"/>
    
    <motor name="lleg_joint1" joint="lleg_joint1" gear="1" ctrllimited="true" ctrlrange="-200 200"/>
    <motor name="lleg_joint2" joint="lleg_joint2" gear="1" ctrllimited="true" ctrlrange="-200 200"/>
    <motor name="lleg_joint3" joint="lleg_joint3" gear="1" ctrllimited="true" ctrlrange="-200 200"/>
    <motor name="lleg_joint4" joint="lleg_joint4" gear="1" ctrllimited="true" ctrlrange="-200 200"/>
    <motor name="lleg_joint5" joint="lleg_joint5" gear="1" ctrllimited="true" ctrlrange="-200 200"/>
    <motor name="lleg_joint6" joint="lleg_joint6" gear="1" ctrllimited="true" ctrlrange="-200 200"/>
    <motor name="rleg_joint1" joint="rleg_joint1" gear="1" ctrllimited="true" ctrlrange="-200 200"/>
    <motor name="rleg_joint2" joint="rleg_joint2" gear="1" ctrllimited="true" ctrlrange="-200 200"/>
    <motor name="rleg_joint3" joint="rleg_joint3" gear="1" ctrllimited="true" ctrlrange="-200 200"/>
    <motor name="rleg_joint4" joint="rleg_joint4" gear="1" ctrllimited="true" ctrlrange="-200 200"/>
    <motor name="rleg_joint5" joint="rleg_joint5" gear="1" ctrllimited="true" ctrlrange="-200 200"/>
    <motor name="rleg_joint6" joint="rleg_joint6" gear="1" ctrllimited="true" ctrlrange="-200 200"/>

  </actuator>

  <sensor>
    <actuatorpos name='lleg_joint1_p'  actuator='lleg_joint1' user='13'/>
    <actuatorpos name='lleg_joint2_p'  actuator='lleg_joint1' user='13'/>
    <actuatorpos name='lleg_joint3_p'  actuator='lleg_joint1' user='13'/>
    <actuatorpos name='lleg_joint4_p'  actuator='lleg_joint1' user='13'/>
    <actuatorpos name='lleg_joint5_p'  actuator='lleg_joint1' user='13'/>
    <actuatorpos name='lleg_joint6_p'  actuator='lleg_joint1' user='13'/>
    <actuatorpos name='rleg_joint1_p'  actuator='rleg_joint1' user='13'/>
    <actuatorpos name='rleg_joint2_p'  actuator='rleg_joint2' user='13'/>
    <actuatorpos name='rleg_joint3_p'  actuator='rleg_joint3' user='13'/>
    <actuatorpos name='rleg_joint4_p'  actuator='rleg_joint4' user='13'/>
    <actuatorpos name='rleg_joint5_p'  actuator='rleg_joint5' user='13'/>
    <actuatorpos name='rleg_joint6_p'  actuator='rleg_joint6' user='13'/>

    <actuatorpos name='waist_yaw_joint_p'  actuator='waist_yaw_joint' user='13'/>
    <actuatorpos name='larm_joint1_p'  actuator='larm_joint1' user='13'/>
    <actuatorpos name='larm_joint2_p'  actuator='larm_joint2' user='13'/>
    <actuatorpos name='larm_joint3_p'  actuator='larm_joint3' user='13'/>
    <actuatorpos name='larm_joint4_p'  actuator='larm_joint4' user='13'/>
    <actuatorpos name='larm_joint5_p'  actuator='larm_joint5' user='13'/>
    <!-- <actuatorpos name='larm_joint6_p'  actuator='larm_joint6' user='13'/> -->
    <actuatorpos name='rarm_joint1_p'  actuator='rarm_joint1' user='13'/>
    <actuatorpos name='rarm_joint2_p'  actuator='rarm_joint2' user='13'/>
    <actuatorpos name='rarm_joint3_p'  actuator='rarm_joint3' user='13'/>
    <actuatorpos name='rarm_joint4_p'  actuator='rarm_joint4' user='13'/>
    <actuatorpos name='rarm_joint5_p'  actuator='rarm_joint5' user='13'/>
    <!-- <actuatorpos name='rarm_joint6_p'  actuator='rarm_joint6' user='13'/> -->

    <actuatorvel name='lleg_joint1_v'  actuator='lleg_joint1' user='13'/>
    <actuatorvel name='lleg_joint2_v'  actuator='lleg_joint2' user='13'/>
    <actuatorvel name='lleg_joint3_v'  actuator='lleg_joint3' user='13'/>
    <actuatorvel name='lleg_joint4_v'  actuator='lleg_joint4' user='13'/>
    <actuatorvel name='lleg_joint5_v'  actuator='lleg_joint5' user='13'/>
    <actuatorvel name='lleg_joint6_v'  actuator='lleg_joint6' user='13'/>
    <actuatorvel name='rleg_joint1_v'  actuator='rleg_joint1' user='13'/>
    <actuatorvel name='rleg_joint2_v'  actuator='rleg_joint2' user='13'/>
    <actuatorvel name='rleg_joint3_v'  actuator='rleg_joint3' user='13'/>
    <actuatorvel name='rleg_joint4_v'  actuator='rleg_joint4' user='13'/>
    <actuatorvel name='rleg_joint5_v'  actuator='rleg_joint5' user='13'/>
    <actuatorvel name='rleg_joint6_v'  actuator='rleg_joint6' user='13'/>

    <actuatorvel name='waist_yaw_joint_v'  actuator='waist_yaw_joint' user='13'/>
    <actuatorvel name='larm_joint1_v'  actuator='larm_joint1' user='13'/>
    <actuatorvel name='larm_joint2_v'  actuator='larm_joint2' user='13'/>
    <actuatorvel name='larm_joint3_v'  actuator='larm_joint3' user='13'/>
    <actuatorvel name='larm_joint4_v'  actuator='larm_joint4' user='13'/>
    <actuatorvel name='larm_joint5_v'  actuator='larm_joint5' user='13'/>
    <!-- <actuatorvel name='larm_joint6_v'  actuator='larm_joint6' user='13'/> -->
    <actuatorvel name='rarm_joint1_v'  actuator='rarm_joint1' user='13'/>
    <actuatorvel name='rarm_joint2_v'  actuator='rarm_joint2' user='13'/>
    <actuatorvel name='rarm_joint3_v'  actuator='rarm_joint3' user='13'/>
    <actuatorvel name='rarm_joint4_v'  actuator='rarm_joint4' user='13'/>
    <actuatorvel name='rarm_joint5_v'  actuator='rarm_joint5' user='13'/>
    <!-- <actuatorvel name='rarm_joint6_v'  actuator='rarm_joint6' user='13'/> -->

    <framequat   name='orientation' objtype='site' objname='imu'/>
    <gyro        name='angular-velocity' site='imu'/>
    <velocimeter name='linear-velocity'  site='imu'/>
  </sensor>
</mujoco>
