<mujoco model="MuJoCo Model">
  <option iterations="50" timestep="0.002" solver="PGS" gravity="0 0 -9.81" />
  <compiler angle="radian" meshdir="meshes/"/>

  <default>
    <joint damping="0.01" armature="0.01" frictionloss="0.01" />
  </default>

  <asset>
    <mesh name="LF_FOOT_WHEEL_visuals" file="LF_FOOT_WHEEL_visuals.obj"/>
    <mesh name="LH_FOOT_WHEEL_visuals" file="LH_FOOT_WHEEL_visuals.obj"/>
    <mesh name="RF_FOOT_WHEEL_visuals" file="RF_FOOT_WHEEL_visuals.obj"/>
    <mesh name="RH_FOOT_WHEEL_visuals" file="RH_FOOT_WHEEL_visuals.obj"/>
    <mesh name="difference_bl_visuals" file="difference_bl_visuals.obj"/>
    <mesh name="difference_br_visuals" file="difference_br_visuals.obj"/>
    <mesh name="difference_fl_visuals" file="difference_fl_visuals.obj"/>
    <mesh name="difference_fr_visuals" file="difference_fr_visuals.obj"/>
    <mesh name="base_visuals_mesh_0" file="base_visuals_mesh_0.obj"/>
    <mesh name="shank_bl_visuals_mesh_0" file="shank_bl_visuals_mesh_0.obj"/>
    <mesh name="shank_br_visuals_mesh_0" file="shank_br_visuals_mesh_0.obj"/>
    <mesh name="shank_fl_visuals_mesh_0" file="shank_fl_visuals_mesh_0.obj"/>
    <mesh name="shank_fr_visuals_mesh_0" file="shank_fr_visuals_mesh_0.obj"/>
    <mesh name="thigh_bl_visuals" file="thigh_bl_visuals.obj"/>
    <mesh name="thigh_br_visuals" file="thigh_br_visuals.obj"/>
    <mesh name="thigh_fl_visuals" file="thigh_fl_visuals.obj"/>
    <mesh name="thigh_fr_visuals" file="thigh_fr_visuals.obj"/>
    
    <texture name="texplane" type="2d" builtin="checker" rgb1=".0 .0 .0" rgb2=".8 .8 .8" width="100" height="100" />
    <material name="matplane" reflectance="0." texture="texplane" texrepeat="1 1" texuniform="true" />
  </asset>

  <worldbody>
    <light directional="true" diffuse="0.4 0.4 0.4" specular="0.1 0.1 0.1" pos="0 0 5.0" dir="0 0 -1" castshadow="false" />
    <light directional="true" diffuse="0.6 0.6 0.6" specular="0.2 0.2 0.2" pos="0 0 4" dir="0 0 -1" />
    <geom name="ground" type="plane" pos="0 0 0" size="100 100 0.001" quat="1 0 0 0" material="matplane" condim="3" conaffinity="15" />
    
    <body name="base" pos="0 0 1">
      <joint name="root" type="free"/>

      <geom type="mesh" contype="0" conaffinity="0" group="1" density="0" mesh="base_visuals_mesh_0"/>
      <geom size="0.0075 0.0075 0.002" type="box" contype="0" conaffinity="0" group="1" density="0"/>
      <geom size="0.241 0.106 0.056" type="box"/>
      <inertial pos="0.0446334 0.0002693 -0.0071156" mass="12.149" diaginertia="0.048576 0.75312 0.75287"/>

      <body name="front" pos="0.4 0 0" zaxis="0 1 0">
        <geom size="0.05 0.08" type="capsule"/>
      </body>
      <body name="back" pos="-0.4 0 0" zaxis="0 1 0">
        <geom size="0.05 0.08" type="capsule"/>
      </body>

      <body name="difference_fr" pos="0.31 0.05 0">
        <inertial pos="3e-07 0.006785 -7.29e-05" quat="0.00505755 0.707089 0.00505755 0.707089" mass="1.83992" diaginertia="0.00248796 0.00218034 0.0015967"/>
        <joint name="LF_HAA" pos="0 0 0" axis="1 0 0" range="-0.785398 0.785398" actuatorfrcrange="-40 40"/>
        <geom type="mesh" contype="0" conaffinity="0" group="1" density="0" mesh="difference_fr_visuals"/>
        <body name="thigh_fr" pos="0 0.0415 0">
          <inertial pos="7.8e-06 0.0767249 -0.0853108" quat="0.997528 0.0688889 0.00138496 -0.0137599" mass="1.84492" diaginertia="0.0200733 0.019769 0.00221105"/>
          <joint name="LF_HFE" pos="0 0 0" axis="0 1 0" range="-1.57 1.57" actuatorfrcrange="-40 40"/>
          <geom type="mesh" contype="0" conaffinity="0" group="1" density="0" mesh="thigh_fr_visuals"/>
          <geom size="0.025 0.02 0.14" pos="0 0.093 -0.135" type="box"/>
          <body name="shank_fr" pos="0 0.0931 -0.270123">
            <inertial pos="-0.041592 -8.9e-06 -0.12216" quat="-0.000183117 0.499265 6.77297e-05 0.866449" mass="0.523946" diaginertia="0.0111486 0.008924 0.00746656"/>
            <joint name="LF_KFE" pos="0 0 0" axis="0 1 0" range="-3.14159 1.17453" actuatorfrcrange="-80 80"/>
            <geom type="mesh" contype="0" conaffinity="0" group="1" density="0" mesh="shank_fr_visuals_mesh_0"/>
            <geom size="0.01" pos="-0.07 0 -0.252" contype="0" conaffinity="0" group="1" density="0"/>
            <geom size="0.016 0.125" pos="-0.055 0 -0.12" type="cylinder"/>
            <geom size="0.01" pos="-0.07 0 -0.252"/>
            <body name="LF_FOOT_WHEEL" pos="-0.07 0.04 -0.252">
              <inertial pos="0 0 0" quat="0.707107 0 0 0.707107" mass="1.5" diaginertia="0.0028937 0.0015556 0.0015556"/>
              <joint name="wheel_1" pos="0 0 0" axis="0 1 0"/>
              <geom type="mesh" contype="0" conaffinity="0" group="1" density="0" mesh="LF_FOOT_WHEEL_visuals"/>
              <geom size="0.0825 0.0235" quat="0.707388 0.706825 0 0" type="cylinder"/>
            </body>
          </body>
        </body>
      </body>
      <body name="difference_br" pos="-0.31 0.05 0">
        <inertial pos="3e-07 0.006785 -7.29e-05" quat="0.00505755 0.707089 0.00505755 0.707089" mass="1.83992" diaginertia="0.00248796 0.00218034 0.0015967"/>
        <joint name="LH_HAA" pos="0 0 0" axis="1 0 0" range="-0.785398 0.785398" actuatorfrcrange="-40 40"/>
        <geom type="mesh" contype="0" conaffinity="0" group="1" density="0" mesh="difference_br_visuals"/>
        <body name="thigh_br" pos="0 0.0415 0">
          <inertial pos="7.8e-06 0.0767249 -0.0853108" quat="0.997528 0.0688889 0.00138496 -0.0137599" mass="1.84492" diaginertia="0.0200733 0.019769 0.00221105"/>
          <joint name="LH_HFE" pos="0 0 0" axis="0 1 0" range="-1.57 1.57" actuatorfrcrange="-40 40"/>
          <geom type="mesh" contype="0" conaffinity="0" group="1" density="0" mesh="thigh_br_visuals"/>
          <geom size="0.025 0.02 0.14" pos="0 0.093 -0.135" type="box"/>
          <body name="shank_br" pos="0 0.0931 -0.270123">
            <inertial pos="0.041592 8.9e-06 -0.12216" quat="-6.77297e-05 0.866449 0.000183117 0.499265" mass="0.523946" diaginertia="0.0111486 0.008924 0.00746656"/>
            <joint name="LH_KFE" pos="0 0 0" axis="0 1 0" range="-1.17453 3.14159" actuatorfrcrange="-80 80"/>
            <geom type="mesh" contype="0" conaffinity="0" group="1" density="0" mesh="shank_br_visuals_mesh_0"/>
            <geom size="0.01" pos="0.07 0 -0.252" contype="0" conaffinity="0" group="1" density="0"/>
            <geom size="0.016 0.125" pos="0.055 0 -0.12" type="cylinder"/>
            <geom size="0.01" pos="0.07 0 -0.252"/>
            <body name="LH_FOOT_WHEEL" pos="0.07 0.04 -0.252">
              <inertial pos="0 0 0" quat="0.707107 0 0 0.707107" mass="1.5" diaginertia="0.0028937 0.0015556 0.0015556"/>
              <joint name="wheel_2" pos="0 0 0" axis="0 1 0"/>
              <geom type="mesh" contype="0" conaffinity="0" group="1" density="0" mesh="LH_FOOT_WHEEL_visuals"/>
              <geom size="0.0825 0.0235" quat="0.707388 0.706825 0 0" type="cylinder"/>
            </body>
          </body>
        </body>
      </body>
      <body name="difference_fl" pos="0.31 -0.05 0">
        <inertial pos="-3e-07 -0.006785 -7.29e-05" quat="-0.00505755 0.707089 -0.00505755 0.707089" mass="1.83992" diaginertia="0.00248796 0.00218034 0.0015967"/>
        <joint name="RF_HAA" pos="0 0 0" axis="1 0 0" range="-0.785398 0.785398" actuatorfrcrange="-40 40"/>
        <geom type="mesh" contype="0" conaffinity="0" group="1" density="0" mesh="difference_fl_visuals"/>
        <body name="thigh_fl" pos="0 -0.0415 0">
          <inertial pos="-7.8e-06 -0.0767249 -0.0853108" quat="0.997528 -0.0688889 -0.00138496 -0.0137599" mass="1.84492" diaginertia="0.0200733 0.019769 0.00221105"/>
          <joint name="RF_HFE" pos="0 0 0" axis="0 1 0" range="-1.57 1.57" actuatorfrcrange="-40 40"/>
          <geom type="mesh" contype="0" conaffinity="0" group="1" density="0" mesh="thigh_fl_visuals"/>
          <geom size="0.025 0.02 0.14" pos="0 -0.093 -0.135" type="box"/>
          <body name="shank_fl" pos="0 -0.0931 -0.270123">
            <inertial pos="-0.041592 -8.9e-06 -0.12216" quat="-0.000183117 0.499265 6.77297e-05 0.866449" mass="0.523946" diaginertia="0.0111486 0.008924 0.00746656"/>
            <joint name="RF_KFE" pos="0 0 0" axis="0 1 0" range="-3.14159 1.17453" actuatorfrcrange="-80 80"/>
            <geom type="mesh" contype="0" conaffinity="0" group="1" density="0" mesh="shank_fl_visuals_mesh_0"/>
            <geom size="0.01" pos="-0.07 0 -0.252" contype="0" conaffinity="0" group="1" density="0"/>
            <geom size="0.016 0.125" pos="-0.055 0 -0.12" type="cylinder"/>
            <geom size="0.01" pos="-0.07 0 -0.252"/>
            <body name="RF_FOOT_WHEEL" pos="-0.07 -0.04 -0.252">
              <inertial pos="0 0 0" quat="0.707107 0 0 0.707107" mass="1.5" diaginertia="0.0028937 0.0015556 0.0015556"/>
              <joint name="wheel_3" pos="0 0 0" axis="0 1 0"/>
              <geom type="mesh" contype="0" conaffinity="0" group="1" density="0" mesh="RF_FOOT_WHEEL_visuals"/>
              <geom size="0.0825 0.0235" quat="0.707388 0.706825 0 0" type="cylinder"/>
            </body>
          </body>
        </body>
      </body>
      <body name="difference_bl" pos="-0.31 -0.05 0">
        <inertial pos="3e-07 0.006785 -7.29e-05" quat="0.00505755 0.707089 0.00505755 0.707089" mass="1.83992" diaginertia="0.00248796 0.00218034 0.0015967"/>
        <joint name="RH_HAA" pos="0 0 0" axis="1 0 0" range="-0.785398 0.785398" actuatorfrcrange="-40 40"/>
        <geom type="mesh" contype="0" conaffinity="0" group="1" density="0" mesh="difference_bl_visuals"/>
        <body name="thigh_bl" pos="0 -0.0415 0">
          <inertial pos="-7.8e-06 -0.0767249 -0.0853108" quat="0.997528 -0.0688889 -0.00138496 -0.0137599" mass="1.84492" diaginertia="0.0200733 0.019769 0.00221105"/>
          <joint name="RH_HFE" pos="0 0 0" axis="0 1 0" range="-1.57 1.57" actuatorfrcrange="-40 40"/>
          <geom type="mesh" contype="0" conaffinity="0" group="1" density="0" mesh="thigh_bl_visuals"/>
          <geom size="0.025 0.02 0.14" pos="0 -0.093 -0.135" type="box"/>
          <body name="shank_bl" pos="0 -0.0931 -0.270123">
            <inertial pos="0.041592 8.9e-06 -0.12216" quat="-6.77297e-05 0.866449 0.000183117 0.499265" mass="0.523946" diaginertia="0.0111486 0.008924 0.00746656"/>
            <joint name="RH_KFE" pos="0 0 0" axis="0 1 0" range="-1.17453 3.14159" actuatorfrcrange="-80 80"/>
            <geom type="mesh" contype="0" conaffinity="0" group="1" density="0" mesh="shank_bl_visuals_mesh_0"/>
            <geom size="0.01" pos="0.07 0 -0.252" contype="0" conaffinity="0" group="1" density="0"/>
            <geom size="0.016 0.125" pos="0.055 0 -0.12" type="cylinder"/>
            <geom size="0.01" pos="0.07 0 -0.252"/>
            <body name="RH_FOOT_WHEEL" pos="0.07 -0.04 -0.252">
              <inertial pos="0 0 0" quat="0.707107 0 0 0.707107" mass="1.5" diaginertia="0.0028937 0.0015556 0.0015556"/>
              <joint name="wheel_4" pos="0 0 0" axis="0 1 0"/>
              <geom type="mesh" contype="0" conaffinity="0" group="1" density="0" mesh="RH_FOOT_WHEEL_visuals"/>
              <geom size="0.0825 0.0235" quat="0.707388 0.706825 0 0" type="cylinder"/>
            </body>
          </body>
        </body>
      </body>
    </body>
  </worldbody>

  <actuator>
    <motor name="LF_HAA" joint="LF_HAA" ctrllimited="true" ctrlrange="-40 40" gear="1" />
    <motor name="LF_HFE" joint="LF_HFE" ctrllimited="true" ctrlrange="-40 40" gear="1" />
    <motor name="LF_KFE" joint="LF_KFE" ctrllimited="true" ctrlrange="-80 80" gear="1" />
    <motor name="wheel_1" joint="wheel_1" ctrllimited="true" ctrlrange="-10 10" gear="1" />
    <motor name="LH_HAA" joint="LH_HAA" ctrllimited="true" ctrlrange="-40 40" gear="1" />
    <motor name="LH_HFE" joint="LH_HFE" ctrllimited="true" ctrlrange="-40 40" gear="1" />
    <motor name="LH_KFE" joint="LH_KFE" ctrllimited="true" ctrlrange="-80 80" gear="1" />
    <motor name="wheel_2" joint="wheel_2" ctrllimited="true" ctrlrange="-10 10" gear="1" />
    <motor name="RF_HAA" joint="RF_HAA" ctrllimited="true" ctrlrange="-40 40" gear="1" />
    <motor name="RF_HFE" joint="RF_HFE" ctrllimited="true" ctrlrange="-40 40" gear="1" />
    <motor name="RF_KFE" joint="RF_KFE" ctrllimited="true" ctrlrange="-80 80" gear="1" />
    <motor name="wheel_3" joint="wheel_3" ctrllimited="true" ctrlrange="-10 10" gear="1" />
    <motor name="RH_HAA" joint="RH_HAA" ctrllimited="true" ctrlrange="-40 40" gear="1" />
    <motor name="RH_HFE" joint="RH_HFE" ctrllimited="true" ctrlrange="-40 40" gear="1" />
    <motor name="RH_KFE" joint="RH_KFE" ctrllimited="true" ctrlrange="-80 80" gear="1" />
    <motor name="wheel_4" joint="wheel_4" ctrllimited="true" ctrlrange="-10 10" gear="1" />
  </actuator>

  <sensor>
    <framelinvel name="base_lin_vel" objtype="body" objname="base"/>
    <frameangvel name="base_ang_vel" objtype="body" objname="base"/>
    <framelinvel name="wheel_lin_vel" objtype="body" objname="RH_FOOT_WHEEL"/>
    <frameangvel name="wheel_ang_vel" objtype="body" objname="RH_FOOT_WHEEL"/>
  </sensor>
</mujoco>
